#7 task 02
print('Line 2 will throw an exception')
a = int("5")
print(a + "5")
print(a * "5")
print(ValueError)
# In line 2